<?xml version="1.0"?>
<!-- portaal_robot Chain -->
<robot name="portaal_robot" xmlns:xacro="http://ros.org/wiki/xacro">


  <material name="LightGrey">
      <color rgba="0.7 0.7 0.7 1.0" />
  </material>

  <material name="LightRed">
      <color rgba="0.7 0 0 1.0" />
  </material>

  <material name="LightBlue">
      <color rgba="0.0 0 0.7 1.0" />
  </material>

  <!-- World -->
  <link name="world"/>

  <joint name="horizontal_arm_world_joint" type="fixed">
    <parent link="world" />
    <child link="horizontal_arm" />
    <origin xyz="0 0 1.2" rpy="0 0 0" />
  </joint>


  <link name="horizontal_arm">
    <inertial>
      <origin xyz="0 0 0" rpy="0 0 0" />
      <inertia ixx="0.1" ixy="0" ixz="0"
               iyy="0.1" iyz="0"
               izz="0.1" />
      <mass value="1" />
    </inertial>
    <visual>
      <origin xyz="0 0 0" />
      <geometry>
        <box size="0.04 1.5 0.04" />
      </geometry>
      <material name="LightRed"/>
    </visual>
  </link>

  <link name="horizontal_train">
    <inertial>
      <origin xyz="0 0 0" rpy="0 0 0" />
      <inertia ixx="0.1" ixy="0" ixz="0"
               iyy="0.1" iyz="0"
               izz="0.1" />
      <mass value="1" />
    </inertial>
    <visual>
      <origin xyz="0 0 0" />
      <geometry>
        <box size="0.04 0.04 0.04" />
      </geometry>
      <material name="LightGrey"/>
    </visual>
  </link>

<!--
  <joint name="horizontal_arm_joint" type="prismatic">
-->

  <joint name="horizontal_arm_joint" type="prismatic">
    <parent link="horizontal_arm" />
    <child link="horizontal_train" />

    <axis xyz="0 1 0" />
    <limit lower="-0.7"
           upper="0.7"
           effort="1000"
           velocity="1" />
    <origin xyz="0.04 0.00 0" rpy="0 0 0" />
    <dynamics damping="20.0" friction="500.0" />
  </joint>


  <link name="vertical_arm">
    <inertial>
      <origin xyz="0 0 0" rpy="0 0 0" />
      <inertia ixx="0.1" ixy="0" ixz="0"
               iyy="0.1" iyz="0"
               izz="0.1" />
      <mass value="1" />
    </inertial>
    <visual>
      <origin xyz="0 0 0" />
      <geometry>
        <box size="0.03 0.03 1.0" />
      </geometry>
      <material name="LightRed"/>
    </visual>
  </link>


  <joint name="vertical_arm_joint" type="prismatic">
    <parent link="horizontal_train" />
    <child link="vertical_arm" />

    <axis xyz="0 0 1" />
    <limit lower="-0.45"
           upper="0.45"
           effort="1000"
           velocity="1" />
    <origin xyz="0.035 0.00 0" rpy="0 0 0" />
    <dynamics damping="20.0" friction="500.0" />
  </joint>

  <link name="vacuum_gripper">
    <visual>
      <origin xyz="0 0 0" />
      <geometry>
        <cylinder radius="0.05" length="0.015"/>
      </geometry>
      <material name="LightBlue"/>
    </visual>
  </link>

  <joint name="gripper_joint" type="fixed">
    <parent link="vertical_arm" />
    <child link="vacuum_gripper" />

    <origin xyz="0.0 0.0 -0.5" rpy="0 0 0" />
    <dynamics damping="20.0" friction="500.0" />
  </joint>
</robot>
