<?xml version="1.0"?>
<!-- portaal_robot Chain -->
<robot name="portaal_robot" xmlns:xacro="http://ros.org/wiki/xacro">

  <xacro:macro name="cylinder_inertia" params="m r h">
        <inertia  ixx="${m*(3*r*r+h*h)/12}" ixy = "0" ixz = "0"
                    iyy="${m*(3*r*r+h*h)/12}" iyz = "0"
                    izz="${m*r*r/2}" />
  </xacro:macro>

  <xacro:macro name="box_inertia" params="m x y z">
          <inertia  ixx="${m*(y*y+z*z)/12}" ixy = "0" ixz = "0"
                    iyy="${m*(x*x+z*z)/12}" iyz = "0"
                    izz="${m*(x*x+z*z)/12}" />
  </xacro:macro>

  <xacro:macro name="sphere_inertia" params="m r">
          <inertia  ixx="${2*m*r*r/5}" ixy = "0" ixz = "0"
                    iyy="${2*m*r*r/5}" iyz = "0"
                    izz="${2*m*r*r/5}" />
  </xacro:macro>

  <material name="LightGrey">
      <color rgba="0.7 0.7 0.7 1.0" />
  </material>

  <material name="LightRed">
      <color rgba="0.7 0 0 1.0" />
  </material>

  <material name="LightBlue">
      <color rgba="0.0 0 0.7 1.0" />
  </material>

  <!-- World -->
  <link name="world"/>

  <joint name="horizontal_arm_world_joint" type="fixed">
    <parent link="world" />
    <child link="horizontal_arm" />
    <origin xyz="0 0 1.2" rpy="0 0 0" />
  </joint>


  <link name="horizontal_arm">
    <inertial>
      <origin xyz="0 0 0" rpy="0 0 0" />
      <mass value="1"/>
      <xacro:box_inertia m="1" x="0.04" y="1.5" z="0.04"/>
    </inertial>
    <visual>
      <origin xyz="0 0 0" />
      <geometry>
        <box size="0.04 1.5 0.04" />
      </geometry>
      <material name="LightRed"/>
    </visual>
  </link>

  <link name="horizontal_train">
    <inertial>
      <origin xyz="0 0 0" rpy="0 0 0" />
      <mass value="0.1"/>
      <xacro:box_inertia m="0.1" x="0.04" y="0.04" z="0.04"/>
    </inertial>
    <visual>
      <origin xyz="0 0 0" />
      <geometry>
        <box size="0.04 0.04 0.04" />
      </geometry>
      <material name="LightGrey"/>
    </visual>
  </link>

<!--
  <joint name="horizontal_arm_joint" type="prismatic">
-->

  <joint name="horizontal_arm_joint" type="prismatic">
    <parent link="horizontal_arm" />
    <child link="horizontal_train" />

    <axis xyz="0 1 0" />
    <limit lower="-0.7"
           upper="0.7"
           effort="1000"
           velocity="1" />
    <origin xyz="0.04 0.00 0" rpy="0 0 0" />
    <dynamics damping="20.0" friction="500.0" />
  </joint>


  <link name="vertical_arm">
    <inertial>
      <origin xyz="0 0 0" rpy="0 0 0" />
      <mass value="0.75"/>
      <xacro:box_inertia m="0.75" x="0.043" y="0.03" z="1.0"/>
    </inertial>
    <visual>
      <origin xyz="0 0 0" />
      <geometry>
        <box size="0.03 0.03 1.0" />
      </geometry>
      <material name="LightRed"/>
    </visual>
  </link>


  <joint name="vertical_arm_joint" type="prismatic">
    <parent link="horizontal_train" />
    <child link="vertical_arm" />

    <axis xyz="0 0 1" />
    <limit lower="-0.45"
           upper="0.45"
           effort="1000"
           velocity="1" />
    <origin xyz="0.035 0.00 0" rpy="0 0 0" />
    <dynamics damping="20.0" friction="500.0" />
  </joint>

  <link name="vacuum_gripper">
    <inertial>
      <origin xyz="0 0 0" rpy="0 0 0" />
      <mass value="1"/>
      <xacro:cylinder_inertia m="1" r="1.5" h="0.015"/>
    </inertial>
    <visual>
      <origin xyz="0 0 0" />
      <geometry>
        <cylinder radius="0.05" length="0.015"/>
      </geometry>
      <material name="LightBlue"/>
    </visual>
  </link>

  <joint name="gripper_joint" type="fixed">
    <parent link="vertical_arm" />
    <child link="vacuum_gripper" />

    <origin xyz="0.0 0.0 -0.5" rpy="0 0 0" />
    <dynamics damping="20.0" friction="500.0" />
  </joint>
</robot>
